Workbook

Sheet May
A1: Date | B1: Task | C1: Amount of time | D1: Daily Total | E1: Weekly total | F1: Monthly:
A2: 45796 | B2: Fill out forms for HR | C2: 0.75 | D2: =SUM(C2:C14) -> 7.5 | E2: =SUM(D2:D43) -> 38
A3: 45796 | B3: Meeting with Hannah | C3: 0.75
A4: 45796 | B4: 25/26 kick off material reading | C4: 0.75
A5: 45796 | B5: Email and admin | C5: 0.75
A6: 45796 | B6: Reading Safeguard document | C6: 1
A7: 45796 | B7: HR introduction | C7: 0.5
A8: 45796 | B8: Staff Behavior Policy | C8: 0.25
A9: 45796 | B9: Healthbox info update | C9: 0.25
A10: 45796 | B10: Touchbase Hannah | C10: 0.25
A11: 45796 | B11: TES Safeguarding (Module 1) | C11: 0.5
A12: 45796 | B12: TES Safeguarding (Module 2) | C12: 1
A13: 45796 | B13: Exploring documentation | C13: 0.25
A14: 45796 | B14: IT Document on DocuSign | C14: 0.5
A15: 45797 | B15: TES Safeguarding (Module 3) | C15: 0.5 | D15: =SUM(C15:C22) -> 7.5
A16: 45797 | B16: TES Safeguarding (Module 4) | C16: 0.5
A17: 45797 | B17: TES Equality and Diversity (Module 1) | C17: 1
A18: 45797 | B18: Safeguarding HR meeting | C18: 0.5
A19: 45797 | B19: TES Equality and Diversity (Module 2) | C19: 0.5
A20: 45797 | B20: TES Prevent duty | C20: 1
A21: 45797 | B21: Review material W1D1 | C21: 2.5
A22: 45797 | B22: Review material W1D2 | C22: 1
A23: 45798 | B23: Review material W1D2 | C23: 1.25 | D23: =SUM(C23:C31) -> 8
A24: 45798 | B24: Review policy documents | C24: 1.25
A25: 45798 | B25: TES Cybersecurity | C25: 0.75
A26: 45798 | B26: Quality induction | C26: 0.75
A27: 45798 | B27: Candidate engagement induction | C27: 0.5
A28: 45798 | B28: Chit chat Wednesday | C28: 0.5
A29: 45798 | B29: TES GDPR | C29: 1
A30: 45798 | B30: Review material W1D3 | C30: 1.5
A31: 45798 | B31: Nearpod exploration | C31: 0.5
A32: 45799 | B32: Review material W1D3 | C32: 1 | D32: =SUM(C32:C38) -> 7.5
A33: 45799 | B33: Prep W1D1 | C33: 2.75
A34: 45799 | B34: Nearpod report download documentation | C34: 0.5
A35: 45799 | B35: Review material W1D4 | C35: 2
A36: 45799 | B36: Review material W2D1 | C36: 0.75
A37: 45799 | B37: Reveiw material W2D2 | C37: 0.25
A38: 45799 | B38: Career support | C38: 0.25
A39: 45800 | B39: Time with Dan | C39: 6 | D39: =SUM(C39:C43) -> 7.5
A40: 45800 | B40: Email and admin | C40: 0.25
...

Sheet June
A1: Date | B1: Task | C1: Amount of time | D1: Daily total | E1: Weekly total | F1: Monthly total | G1: Theoretical hours | H1: Diff
A2: 45810 | B2: Review material W3D2 | C2: 0.5 | D2: =SUM(C2:C6) -> 7.75 | E2: =SUM(D2, D7, D11, D16, D20) -> 38.25 | F2: =SUM(E2, E26, E45, E62, E83) -> 167.75 | G2: =COUNT(_xlfn.UNIQUE(A:A))*7.5 -> 157.5 | H2: =F2-G2 -> 10.25
A3: 45810 | B3: Review material W3D3 | C3: 3
A4: 45810 | B4: 25/26 kick off material reading | C4: 2.25 | F4: CPD hours
A5: 45810 | B5: Installing MySQL | C5: 1 | F5: =SUMIF(_xlfn._TRO_ALL(B:B), "*Data Camp CPD*",_xlfn._TRO_ALL( C:C)) -> 13.5
A6: 45810 | B6: Review materiel W4D1 | C6: 1
A7: 45811 | B7: Review material W4D1 | C7: 1.5 | D7: =SUM(C7:C10) -> 7.5 | F7: Total student feedback
A8: 45811 | B8: Review material W4D2 | C8: 4 | F8: =SUMIF(_xlfn._TRO_ALL(B:B), "*student feedback*",_xlfn._TRO_ALL( C:C)) -> 20
A9: 45811 | B9: Review material W4D3 | C9: 1.75
A10: 45811 | B10: Review material W4D4 | C10: 0.25
A11: 45812 | B11: Review material W4D4 | C11: 1.5 | D11: =SUM(C11:C15) -> 7.75
A12: 45812 | B12: Review material W5D1 | C12: 1
A13: 45812 | B13: Meeting with Hannah | C13: 1
A14: 45812 | B14: Introduction to Tableau Data Camp CPD | C14: 4
A15: 45812 | B15: Weekly ChitChat | C15: 0.25
A16: 45813 | B16: Introduction to Power BI Data Camp CPD | C16: 3.5 | D16: =SUM(C16:C19) -> 7.5
A17: 45813 | B17: Meeting John Parkin | C17: 0.5
A18: 45813 | B18: Skillable practice | C18: 1
A19: 45813 | B19: Introduction to Excel Data Camp CPD | C19: 2.5
A20: 45814 | B20: Check in with Christian | C20: 1 | D20: =SUM(C20:C24) -> 7.75
A21: 45814 | B21: Prep for setup, practice with Nearpod, slides management | C21: 2
A22: 45814 | B22: Quick check in with Yusuf | C22: 0.25
A23: 45814 | B23: Analyzing Data in Tableau (Preparing for Analysis) Data Camp CPD | C23: 3.5
A24: 45814 | B24: Data team catch up | C24: 1
A25: 45814 | B25: Exploring teams' Teams | C25: 0.25
A26: 45817 | B26: Teaching | C26: 6 | D26: =SUM(C26:C28) -> 7.5 | E26: =SUM(D26:D44) -> 39
A27: 45817 | B27: Prep for setup, class revision | C27: 0.75
A28: 45817 | B28: Follow ups for students, setting up documents in Teams | C28: 0.75
A29: 45818 | B29: Teaching | C29: 6 | D29: =SUM(C29:C31) -> 7.5
A30: 45818 | B30: Prep for setup, class revision | C30: 0.75
A31: 45818 | B31: Prep documents for feedback process | C31: 0.75
A32: 45819 | B32: Teaching | C32: 6 | D32: =SUM(C32:C37) -> 8.25
A33: 45819 | B33: Prep for setup, class revision | C33: 0.75
A34: 45819 | B34: Chit chat Wednesday | C34: 0.25
A35: 45819 | B35: Prep documents for feedback process | C35: 0.5
A36: 45819 | B36: Touchbase with Hannah | C36: 0.5
A37: 45819 | B37: LAR form filled | C37: 0.25
A38: 45820 | B38: Teaching | C38: 6 | D38: =SUM(C38:C41) -> 7.75
A39: 45820 | B39: Prep for setup, class revision | C39: 0.75
A40: 45820 | B40: Prep Teams channel for next week | C40: 0.75
...

Sheet July
A1: Date | B1: Task | C1: Amount of time | D1: Daily total | E1: Weekly total | F1: Monthly total | G1: Theoretical hours | H1: Diff
A2: 45839 | B2: Preparing Week 4 Day 2 | C2: 3.5 | D2: =SUM(C2:C5) -> 7.75 | E2: =SUM(D2, D6, D12, D19) -> 30.25 | F2: =SUM(E2,E25,E45,E67, E85) -> 174.75 | G2: =COUNT(_xlfn.UNIQUE(A:A))*7.5 -> 172.5 | H2: =F2-G2 -> 2.25
A3: 45839 | B3: Feedback process improvement | C3: 0.5
A4: 45839 | B4: 25/26 kick off material reading | C4: 3.5 | F4: CPD hours
A5: 45839 | B5: Preparing Week 5 Day 4 | C5: 0.25 | F5: =SUMIF(_xlfn._TRO_ALL(B:B), "*Data Camp CPD*",_xlfn._TRO_ALL( C:C)) -> 25.25
A6: 45840 | B6: Preparing Week 5 Day 4 | C6: 4 | D6: =SUM(C6:C11) -> 7.5
A7: 45840 | B7: Preparing Week 6 Day 1 | C7: 1 | F7: Total student feedback
A8: 45840 | B8: Preparing Week 6 Day 2 | C8: 0.5 | F8: =SUMIF(_xlfn._TRO_ALL(B:B), "Student feedback",_xlfn._TRO_ALL( C:C)) -> 14
A9: 45840 | B9: Preparing Week 6 Day 3 | C9: 0.5
A10: 45840 | B10: Preparing Week 4 Day 3 | C10: 1.25
A11: 45840 | B11: Follow up with Jonathan Winter (find the right video) | C11: 0.25
A12: 45841 | B12: Preparing Week 4 Day 4 | C12: 1 | D12: =SUM(C12:C18) -> 7.75
A13: 45841 | B13: Preparing Week 6 Day 4 | C13: 0.25
A14: 45841 | B14: Skillable Azure | C14: 1.25
A15: 45841 | B15: Canvas | C15: 1.5
A16: 45841 | B16: Google sites | C16: 3
A17: 45841 | B17: Insert data in learner profile | C17: 0.5
A18: 45841 | B18: Touchbase Leigh | C18: 0.25
A19: 45842 | B19: Go through workbooks | C19: 0.5 | D19: =SUM(C19:C24) -> 7.25
A20: 45842 | B20: Skillable Azure | C20: 1.5
A21: 45842 | B21: Preparing Week 4 Day 4 | C21: 0.5
A22: 45842 | B22: Setup Week 4 in Teams + feedback process | C22: 0.75
A23: 45842 | B23: Follow up LAR with Hannah | C23: 0.25
A24: 45842 | B24: Data manipulation with pandas Data Camp CPD | C24: 3.75
A25: 45845 | B25: Prep for setup, class revision | C25: 0.75 | D25: =SUM(C25:C28) -> 7.5 | E25: =SUM(D25, D29, D33, D38, D41) -> 39
A26: 45845 | B26: Teaching | C26: 6
A27: 45845 | B27: Student feedback | C27: 0.5
A28: 45845 | B28: Admin | C28: 0.25
A29: 45846 | B29: Prep for setup, class revision | C29: 0.75 | D29: =SUM(C29:C32) -> 7.5
A30: 45846 | B30: Teaching | C30: 6
A31: 45846 | B31: Meeting Progress Tracking | C31: 0.5
A32: 45846 | B32: Follow up - Leigh | C32: 0.25
A33: 45847 | B33: Prep for setup, class revision | C33: 0.5 | D33: =SUM(C33:C37) -> 8.5
A34: 45847 | B34: Teaching (support students for labs) | C34: 7
A35: 45847 | B35: Support student for portfolio | C35: 0.25
A36: 45847 | B36: Raising LARs | C36: 0.5
A37: 45847 | B37: Code for intervention counter | C37: 0.25
A38: 45848 | B38: Prep for setup, class revision | C38: 0.5 | D38: =SUM(C38:C40) -> 7.5
A39: 45848 | B39: Teaching | C39: 6
A40: 45848 | B40: Code for intervention counter | C40: 1
...

Sheet August
A1: Date | B1: Task | C1: Amount of time | D1: Daily total | E1: Weekly total | F1: Monthly total | G1: Theoretical hours | H1: Diff
A2: 45870 | B2: Case Study: Analyzing Customer Churn in Power BI Data Camp CPD | C2: 3 | D2: =SUMIF(_xlfn._TRO_ALL(A:A), A2,_xlfn._TRO_ALL( C:C)) -> 7.75 | E2: {=SUM(_xlfn.MAP(A2:INDEX(A:A, COUNTA(A:A)), C2:INDEX(C:C, COUNTA(C:C)), _xlfn.LAMBDA(_xlpm.a,_xlpm.b, IF(WEEKNUM(_xlpm.a)=WEEKNUM(A2), _xlpm.b, 0))))} -> 7.75 | F2: =SUM(_xlfn._TRO_ALL(E:E)) -> 163.75 | G2: =COUNT(_xlfn.UNIQUE(A:A))*7.5 -> 157.5 | H2: =F2-G2 -> 6.25
A3: 45870 | B3: Working on student feedback dashboard | C3: 1
A4: 45870 | B4: 25/26 kick off material reading | C4: 0.75 | F4: CPD hours
A5: 45870 | B5: Meetup with newbies | C5: 1.25 | F5: =SUMIF(_xlfn._TRO_ALL(B:B), "*Data Camp CPD*",_xlfn._TRO_ALL( C:C)) -> 8.5
A6: 45870 | B6: Follow ups | C6: 0.5
A7: 45870 | B7: Prep Week 1 | C7: 1.25 | F7: Total Student feedback
A8: 45873 | B8: Prep for class, setup | C8: 1 | D8: =SUMIF(_xlfn._TRO_ALL(A:A), A8,_xlfn._TRO_ALL( C:C)) -> 7.5 | E8: {=SUM(_xlfn.MAP(A2:INDEX(A:A, COUNTA(A:A)), C2:INDEX(C:C, COUNTA(C:C)), _xlfn.LAMBDA(_xlpm.a,_xlpm.b, IF(WEEKNUM(_xlpm.a)=WEEKNUM(A8), _xlpm.b, 0))))} -> 40.5 | F8: =SUMIF(_xlfn._TRO_ALL(B:B), "Student feedback",_xlfn._TRO_ALL( C:C)) -> 25
A9: 45873 | B9: Teaching | C9: 6
A10: 45873 | B10: Post teaching admin work | C10: 0.5
A11: 45874 | B11: Prep for class, setup | C11: 1 | D11: =SUMIF(_xlfn._TRO_ALL(A:A), A11,_xlfn._TRO_ALL( C:C)) -> 8
A12: 45874 | B12: Teaching | C12: 6
A13: 45874 | B13: Check on the graduation video | C13: 1
A14: 45875 | B14: Prep for class, setup | C14: 0.75 | D14: =SUMIF(_xlfn._TRO_ALL(A:A), A14,_xlfn._TRO_ALL( C:C)) -> 7.25
A15: 45875 | B15: Teaching | C15: 6
A16: 45875 | B16: Working on time sheet to get professional development hours | C16: 0.5
A17: 45876 | B17: Prep for class, setup | C17: 0.75 | D17: =SUMIF(_xlfn._TRO_ALL(A:A), A17,_xlfn._TRO_ALL( C:C)) -> 8.75
A18: 45876 | B18: Teaching | C18: 6
A19: 45876 | B19: Prep feedback for Progress Tracker | C19: 1.25
A20: 45876 | B20: Student feedback | C20: 0.75
A21: 45877 | B21: Student feedback | C21: 8 | D21: =SUMIF(_xlfn._TRO_ALL(A:A), A21,_xlfn._TRO_ALL( C:C)) -> 9
A22: 45877 | B22: Team meeting | C22: 1
A23: 45880 | B23: Prep for class, setup | C23: 1 | D23: =SUMIF(_xlfn._TRO_ALL(A:A), A23,_xlfn._TRO_ALL( C:C)) -> 7.5 | E23: {=SUM(_xlfn.MAP(A17:INDEX(A:A, COUNTA(A:A)), C17:INDEX(C:C, COUNTA(C:C)), _xlfn.LAMBDA(_xlpm.a,_xlpm.b, IF(WEEKNUM(_xlpm.a)=WEEKNUM(A23), _xlpm.b, 0))))} -> 39
A24: 45880 | B24: Teaching | C24: 6
A25: 45880 | B25: Student feedback | C25: 0.5
A26: 45881 | B26: Prep for class, setup | C26: 0.75 | D26: =SUMIF(_xlfn._TRO_ALL(A:A), A26,_xlfn._TRO_ALL( C:C)) -> 7.5
A27: 45881 | B27: Teaching | C27: 6
A28: 45881 | B28: Raising LAR's | C28: 0.5
A29: 45881 | B29: Layout progress tracker | C29: 0.25
A30: 45882 | B30: Prep for class, setup | C30: 0.5 | D30: =SUMIF(_xlfn._TRO_ALL(A:A), A30,_xlfn._TRO_ALL( C:C)) -> 7.75
A31: 45882 | B31: Teaching | C31: 6
A32: 45882 | B32: Pension update meeting | C32: 0.75
A33: 45882 | B33: General admin | C33: 0.5
A34: 45883 | B34: Prep for class, setup | C34: 0.5 | D34: =SUMIF(_xlfn._TRO_ALL(A:A), A34,_xlfn._TRO_ALL( C:C)) -> 8.25
A35: 45883 | B35: Teaching | C35: 6
A36: 45883 | B36: Student support | C36: 0.25
A37: 45883 | B37: Studend feedback | C37: 1.5
A38: 45884 | B38: Admin and student support | C38: 0.25 | D38: =SUMIF(_xlfn._TRO_ALL(A:A), A38,_xlfn._TRO_ALL( C:C)) -> 8
A39: 45884 | B39: Student feedback | C39: 6.75
A40: 45884 | B40: Touchbase with Hannah (LAR, vacation, Progress Tracker) | C40: 0.25
...

Sheet September
A1: Date | B1: Task | C1: Amount of time | D1: Daily total | E1: Weekly total | F1: Monthly total | G1: Theoretical hours | H1: Diff
A2: 45901 | B2: Prep for class, setup | C2: 0.5 | D2: =SUMIF(_xlfn._TRO_ALL(A:A), A2,_xlfn._TRO_ALL( C:C)) -> 7.5 | E2: {=SUM(_xlfn.MAP(A2:INDEX(A:A, COUNTA(A:A)), C2:INDEX(C:C, COUNTA(C:C)), _xlfn.LAMBDA(_xlpm.a,_xlpm.b, IF(WEEKNUM(_xlpm.a)=WEEKNUM(A2), _xlpm.b, 0))))} -> 38 | F2: =SUM(_xlfn._TRO_ALL(C:C)) -> 166.25 | G2: =COUNT(_xlfn.UNIQUE(A:A))*7.5 -> 165 | H2: =F2-G2 -> 1.25
A3: 45901 | B3: Teaching | C3: 5.25
A4: 45901 | B4: Grading workbook | C4: 1 | F4: CPD hours
A5: 45901 | B5: Data Modeling in Power BI Data Camp CPD | C5: 0.75 | F5: =SUMIF(_xlfn._TRO_ALL(B:B), "*Data Camp CPD*",_xlfn._TRO_ALL( C:C)) -> 9.75
A6: 45902 | B6: Prep for class, setup | C6: 0.25 | D6: =SUMIF(_xlfn._TRO_ALL(A:A), A6,_xlfn._TRO_ALL( C:C)) -> 7.25
A7: 45902 | B7: Teaching | C7: 6 | F7: Total student feedback
A8: 45902 | B8: Student support | C8: 0.5 | F8: =SUMIF(_xlfn._TRO_LEADING(B:B), "*student feedback*",_xlfn._TRO_ALL( C:C)) -> 8.5
A9: 45902 | B9: Student feedback | C9: 0.5
A10: 45903 | B10: Prep for class, setup | C10: 0.75 | D10: =SUMIF(_xlfn._TRO_ALL(A:A), A10,_xlfn._TRO_ALL( C:C)) -> 8.25
A11: 45903 | B11: Teaching | C11: 6.5
A12: 45903 | B12: Student feedback | C12: 0.75
A13: 45903 | B13: LAR follow up | C13: 0.25
A14: 45904 | B14: Prep for class, setup | C14: 0.5 | D14: =SUMIF(_xlfn._TRO_ALL(A:A), A14,_xlfn._TRO_ALL( C:C)) -> 7.75
A15: 45904 | B15: Teaching | C15: 6
A16: 45904 | B16: Prep for next week | C16: 0.25
A17: 45904 | B17: Student feedback | C17: 1
A18: 45905 | B18: Meeting with Jonathan about OneFile | C18: 1.25 | D18: =SUMIF(_xlfn._TRO_ALL(A:A), A18,_xlfn._TRO_ALL( C:C)) -> 7.25
A19: 45905 | B19: Catch-up with Leigh about learner | C19: 1.25
A20: 45905 | B20: Data catch up with Anna | C20: 1.25
A21: 45905 | B21: Student feedback | C21: 1.75
A22: 45905 | B22: Apprenticeship feedback for Christian | C22: 1.25
A23: 45905 | B23: Student support | C23: 0.25
A24: 45905 | B24: General admin | C24: 0.25
A25: 45908 | B25: Prep for class, setup | C25: 1 | D25: =SUMIF(_xlfn._TRO_ALL(A:A), A25,_xlfn._TRO_ALL( C:C)) -> 7.5 | E25: {=SUM(_xlfn.MAP(A2:INDEX(A:A, COUNTA(A:A)), C2:INDEX(C:C, COUNTA(C:C)), _xlfn.LAMBDA(_xlpm.a,_xlpm.b, IF(WEEKNUM(_xlpm.a)=WEEKNUM(A25), _xlpm.b, 0))))} -> 38.5
A26: 45908 | B26: Teaching | C26: 6
A27: 45908 | B27: Student support | C27: 0.5
A28: 45909 | B28: Prep for class, setup | C28: 0.75 | D28: =SUMIF(_xlfn._TRO_ALL(A:A), A28,_xlfn._TRO_ALL( C:C)) -> 8.25
A29: 45909 | B29: Teaching | C29: 6.25
A30: 45909 | B30: Going through Learner Walk documentation | C30: 1.25
A31: 45910 | B31: Prep for class, setup | C31: 0.75 | D31: =SUMIF(_xlfn._TRO_ALL(A:A), A31,_xlfn._TRO_ALL( C:C)) -> 7.5
A32: 45910 | B32: Teaching | C32: 6
A33: 45910 | B33: General admin | C33: 0.75
A34: 45911 | B34: Prep for class, setup | C34: 0.5 | D34: =SUMIF(_xlfn._TRO_ALL(A:A), A34,_xlfn._TRO_ALL( C:C)) -> 7.5
A35: 45911 | B35: Teaching | C35: 6
A36: 45911 | B36: Student feedback | C36: 1
A37: 45912 | B37: Catch-up with Hannah | C37: 0.5 | D37: =SUMIF(_xlfn._TRO_ALL(A:A), A37,_xlfn._TRO_ALL( C:C)) -> 7.75
A38: 45912 | B38: Student feedback | C38: 3.25
A39: 45912 | B39: Keeping updated about safeguarding | C39: 0.75
A40: 45912 | B40: General admin | C40: 0.75
...

Sheet October
A1: Date | B1: Task | C1: Amount of time | D1: Daily total | E1: Weekly total | F1: Monthly total | G1: Theoretical hours | H1: Diff
A2: 45931 | B2: Prep for class, setup | C2: 0.75 | D2: =SUMIF(_xlfn._TRO_ALL(A:A), A2,_xlfn._TRO_ALL( C:C)) -> 7.25 | E2: {=SUM(_xlfn.MAP(A2:INDEX(A:A, COUNTA(A:A)), C2:INDEX(C:C, COUNTA(C:C)), _xlfn.LAMBDA(_xlpm.a,_xlpm.b, IF(WEEKNUM(_xlpm.a)=WEEKNUM(A2), _xlpm.b, 0))))} -> 22.25 | F2: =SUM(_xlfn._TRO_ALL(C:C)) -> 191 | G2: =(COUNT(_xlfn.UNIQUE(A:A))-1)*7.5 -> 172.5 | H2: =F2-G2 -> 18.5
A3: 45931 | B3: Teaching | C3: 6
A4: 45931 | B4: Student feedback prep | C4: 0.25 | F4: CPD hours
A5: 45931 | B5: Follow up with Anna for lesson | C5: 0.25 | F5: =SUMIF(_xlfn._TRO_ALL(B:B), "*CPD*",_xlfn._TRO_ALL( C:C)) -> 55.25
A6: 45932 | B6: Prep for class, setup | C6: 0.75 | D6: =SUMIF(_xlfn._TRO_ALL(A:A), A6,_xlfn._TRO_ALL( C:C)) -> 7.75
A7: 45932 | B7: Teaching | C7: 6.25 | F7: Total student feedback
A8: 45932 | B8: 1:1 with Hannah | C8: 0.75 | F8: =SUMIF(_xlfn._TRO_LEADING(B:B), "*student feedback*",_xlfn._TRO_ALL( C:C)) -> 15.75
A9: 45933 | B9: Prep for class, setup | C9: 0.75 | D9: =SUMIF(_xlfn._TRO_ALL(A:A), A9,_xlfn._TRO_ALL( C:C)) -> 7.25
A10: 45933 | B10: Teaching | C10: 6.5
A11: 45936 | B11: AET Training CPD (personal work - portfolio) | C11: 1.25 | D11: =SUMIF(_xlfn._TRO_ALL(A:A), A11,_xlfn._TRO_ALL( C:C)) -> 7.5 | E11: {=SUM(_xlfn.MAP(A2:INDEX(A:A, COUNTA(A:A)), C2:INDEX(C:C, COUNTA(C:C)), _xlfn.LAMBDA(_xlpm.a,_xlpm.b, IF(WEEKNUM(_xlpm.a)=WEEKNUM(A11), _xlpm.b, 0))))} -> 37.5
A12: 45936 | B12: General admin | C12: 0.25
A13: 45936 | B13: MFS Learner Walk document | C13: 1.75
A14: 45936 | B14: Apprenticeship prep (M1) | C14: 1.5
A15: 45936 | B15: Understanding Artificial Intelligence Data Camp CPD | C15: 1.25
A16: 45936 | B16: AET Training CPD (personal work - microteach) | C16: 1.5
A17: 45937 | B17: AET Training CPD (personal work - microteach) | C17: 0.25 | D17: =SUMIF(_xlfn._TRO_ALL(A:A), A17,_xlfn._TRO_ALL( C:C)) -> 8
A18: 45937 | B18: Understanding Artificial Intelligence Data Camp CPD | C18: 1.75
A19: 45937 | B19: Apprenticeship prep (M1) | C19: 0.75
A20: 45937 | B20: Apprenticeship prep (M1.2) | C20: 3.5
A21: 45937 | B21: Understanding ChatGPT Data Camp CPD | C21: 1
A22: 45937 | B22: Creating dashboards in Tableau Data Camp CPD | C22: 0.75
A23: 45938 | B23: Creating dashboards in Tableau Data Camp CPD | C23: 3.25 | D23: =SUMIF(_xlfn._TRO_ALL(A:A), A23,_xlfn._TRO_ALL( C:C)) -> 7.25
A24: 45938 | B24: General admin | C24: 0.25
A25: 45938 | B25: OneFile exploration | C25: 0.5
A26: 45938 | B26: Follow up with Alaa (covering his class tomorrow) | C26: 0.25
A27: 45938 | B27: Improve feedback process | C27: 3
A28: 45939 | B28: Prep for class, setup | C28: 1 | D28: =SUMIF(_xlfn._TRO_ALL(A:A), A28,_xlfn._TRO_ALL( C:C)) -> 7.75
A29: 45939 | B29: Teaching | C29: 5.75
A30: 45939 | B30: Monthly Business update | C30: 0.75
A31: 45939 | B31: General admin | C31: 0.25
A32: 45940 | B32: Understanding machine learning Data Camp CPD | C32: 1.5 | D32: =SUMIF(_xlfn._TRO_ALL(A:A), A32,_xlfn._TRO_ALL( C:C)) -> 7
A33: 45940 | B33: Data team meeting | C33: 1.5
A34: 45940 | B34: Improve feedback process | C34: 2
A35: 45940 | B35: AET Training CPD (personal work - portfolio) | C35: 2
A36: 45943 | B36: Prompt engineering with the OpenAI API Data Camp CPD | C36: 1.75 | D36: =SUMIF(_xlfn._TRO_ALL(A:A), A36,_xlfn._TRO_ALL( C:C)) -> 7.5 | E36: {=SUM(_xlfn.MAP(A2:INDEX(A:A, COUNTA(A:A)), C2:INDEX(C:C, COUNTA(C:C)), _xlfn.LAMBDA(_xlpm.a,_xlpm.b, IF(WEEKNUM(_xlpm.a)=WEEKNUM(A36), _xlpm.b, 0))))} -> 37
A37: 45943 | B37: AET Training CPD (personal work - portfolio) | C37: 5.25
A38: 45943 | B38: Support Anna for feedback process | C38: 0.5
A39: 45944 | B39: Prompt engineering with the OpenAI API Data Camp CPD | C39: 2.25 | D39: =SUMIF(_xlfn._TRO_ALL(A:A), A39,_xlfn._TRO_ALL( C:C)) -> 7.5
A40: 45944 | B40: Career Session shadowing Leigh | C40: 2.75
...

Sheet November
A1: Date | B1: Task | C1: Amount of time | D1: Daily total | E1: Weekly total | F1: Monthly total | G1: Theoretical hours | H1: Diff
A2: 45962 | B2: AET Training CPD (personal work - portfolio) | C2: 2.5 | D2: =SUMIF(_xlfn._TRO_ALL(A:A), A2,_xlfn._TRO_ALL( C:C)) -> 2.5 | E2: {=SUM(_xlfn.MAP(A2:INDEX(A:A, COUNTA(A:A)), C2:INDEX(C:C, COUNTA(C:C)), _xlfn.LAMBDA(_xlpm.a,_xlpm.b, IF(WEEKNUM(_xlpm.a)=WEEKNUM(A2), _xlpm.b, 0))))} -> 2.5 | F2: =SUM(_xlfn._TRO_ALL(C:C)) -> 161.25 | G2: =(COUNT(_xlfn.UNIQUE(A:A))-3)*7.5 -> 150 | H2: =F2-G2 -> 11.25
A3: 45963 | B3: AET Training CPD (personal work - portfolio) | C3: 1.5 | D3: =SUMIF(_xlfn._TRO_ALL(A:A), A3,_xlfn._TRO_ALL( C:C)) -> 1.5
A4: 45964 | B4: General admin | C4: 0.25 | D4: =SUMIF(_xlfn._TRO_ALL(A:A), A4,_xlfn._TRO_ALL( C:C)) -> 8.5 | E4: {=SUM(_xlfn.MAP(A2:INDEX(A:A, COUNTA(A:A)), C2:INDEX(C:C, COUNTA(C:C)), _xlfn.LAMBDA(_xlpm.a,_xlpm.b, IF(WEEKNUM(_xlpm.a)=WEEKNUM(A4, 2), _xlpm.b, 0))))} -> 41.25 | F4: CPD hours
A5: 45964 | B5: Student feedback - Bootcamp | C5: 0.75 | F5: =SUMIF(_xlfn._TRO_ALL(B:B), "*CPD*",_xlfn._TRO_ALL( C:C)) -> 12.25
A6: 45964 | B6: Prep for class, setup | C6: 0.5
A7: 45964 | B7: Teaching | C7: 6.25 | F7: Total student feedback
A8: 45964 | B8: Scottish Widow meeting | C8: 0.75 | F8: =SUMIF(_xlfn._TRO_LEADING(B:B), "*student feedback*",_xlfn._TRO_ALL( C:C)) -> 21.5
A9: 45965 | B9: General admin | C9: 0.5 | D9: =SUMIF(_xlfn._TRO_ALL(A:A), A9,_xlfn._TRO_ALL( C:C)) -> 8
A10: 45965 | B10: Student feedback - Bootcamp | C10: 0.5
A11: 45965 | B11: Prep for class, setup | C11: 0.5
A12: 45965 | B12: Teaching | C12: 6.5
A13: 45966 | B13: General admin | C13: 0.5 | D13: =SUMIF(_xlfn._TRO_ALL(A:A), A13,_xlfn._TRO_ALL( C:C)) -> 8
A14: 45966 | B14: Prep for class, setup | C14: 0.75
A15: 45966 | B15: Teaching | C15: 6.25
A16: 45966 | B16: Student feedback - Bootcamp | C16: 0.5
A17: 45967 | B17: Prep for class, setup | C17: 0.25 | D17: =SUMIF(_xlfn._TRO_ALL(A:A), A17,_xlfn._TRO_ALL( C:C)) -> 7.5
A18: 45967 | B18: Teaching | C18: 6.5
A19: 45967 | B19: General admin | C19: 0.5
A20: 45967 | B20: Student feedback - Bootcamp | C20: 0.25
A21: 45968 | B21: General admin | C21: 0.25 | D21: =SUMIF(_xlfn._TRO_ALL(A:A), A21,_xlfn._TRO_ALL( C:C)) -> 7.75
A22: 45968 | B22: Student feedback - Bootcamp | C22: 2.5
A23: 45968 | B23: AET Training CPD (presence) | C23: 4
A24: 45968 | B24: AET Training CPD (personal work - portfolio) | C24: 0.25
A25: 45968 | B25: Walkthrough post observation with Afsha CPD | C25: 0.75
A26: 45970 | B26: Student feedback - Bootcamp | C26: 0.75 | D26: =SUMIF(_xlfn._TRO_ALL(A:A), A26,_xlfn._TRO_ALL( C:C)) -> 1 | E26: {=SUM(_xlfn.MAP(A2:INDEX(A:A, COUNTA(A:A)), C2:INDEX(C:C, COUNTA(C:C)), _xlfn.LAMBDA(_xlpm.a,_xlpm.b, IF(WEEKNUM(_xlpm.a)=WEEKNUM(A26), _xlpm.b, 0))))} -> 42.5
A27: 45970 | B27: General admin | C27: 0.25
A28: 45971 | B28: Prep for class, setup | C28: 0.75 | D28: =SUMIF(_xlfn._TRO_ALL(A:A), A28,_xlfn._TRO_ALL( C:C)) -> 8.5
A29: 45971 | B29: Teaching | C29: 6.5
A30: 45971 | B30: Student feedback - Bootcamp | C30: 0.25
A31: 45971 | B31: AET Training CPD (personal work - portfolio) | C31: 0.25
A32: 45971 | B32: Providing advice for learner in previous group | C32: 0.25
A33: 45971 | B33: General admin | C33: 0.5
A34: 45972 | B34: General admin | C34: 0.75 | D34: =SUMIF(_xlfn._TRO_ALL(A:A), A34,_xlfn._TRO_ALL( C:C)) -> 7.75
A35: 45972 | B35: Prep for class, setup | C35: 0.5
A36: 45972 | B36: Teaching | C36: 6
A37: 45972 | B37: Follow up with learner who missed classes for health reasons | C37: 0.25
A38: 45972 | B38: Student feedback - Bootcamp | C38: 0.25
A39: 45973 | B39: General admin | C39: 0.25 | D39: =SUMIF(_xlfn._TRO_ALL(A:A), A39,_xlfn._TRO_ALL( C:C)) -> 7.5
A40: 45973 | B40: Prep for class, setup | C40: 0.25
...

Sheet December
A1: Date | B1: Task | C1: Amount of time | D1: Daily total | E1: Weekly total | F1: Monthly total | G1: Theoretical hours | H1: Diff
A2: 45992 | B2: Prep for class, setup | C2: 0.25 | D2: =SUMIF(_xlfn._TRO_ALL(A:A), A2,_xlfn._TRO_ALL( C:C)) -> 7.25 | E2: {=SUM(_xlfn.MAP(A2:INDEX(A:A, COUNTA(A:A)), C2:INDEX(C:C, COUNTA(C:C)), _xlfn.LAMBDA(_xlpm.a,_xlpm.b, IF(WEEKNUM(_xlpm.a)=WEEKNUM(A2), _xlpm.b, 0))))} -> 39.75 | F2: =SUM(_xlfn._TRO_ALL(C:C)) -> 55.75 | G2: =COUNT(_xlfn.UNIQUE(A:A))* 7.5 -> 52.5 | H2: =F2-G2 -> 3.25
A3: 45992 | B3: New week setup | C3: 0.25
A4: 45992 | B4: Teaching | C4: 6 | F4: CPD hours
A5: 45992 | B5: Feedback process improvement for workbook | C5: 0.75 | F5: =SUMIF(_xlfn._TRO_ALL(B:B), "*CPD*",_xlfn._TRO_ALL( C:C)) -> 0
A6: 45993 | B6: Prep for class, setup | C6: 0.5 | D6: =SUMIF(_xlfn._TRO_ALL(A:A), A6,_xlfn._TRO_ALL( C:C)) -> 7.5
A7: 45993 | B7: Teaching | C7: 6.25 | F7: Total student feedback
A8: 45993 | B8: General admin | C8: 0.75 | F8: =SUMIF(_xlfn._TRO_LEADING(B:B), "*student feedback*",_xlfn._TRO_ALL( C:C)) -> 8.25
A9: 45994 | B9: Prep for class, setup | C9: 0.75 | D9: =SUMIF(_xlfn._TRO_ALL(A:A), A9,_xlfn._TRO_ALL( C:C)) -> 9
A10: 45994 | B10: Teaching | C10: 6
A11: 45994 | B11: MFS OTLA prep with Afsha | C11: 1
A12: 45994 | B12: Prep for OTLA | C12: 1
A13: 45994 | B13: General admin | C13: 0.25
A14: 45995 | B14: Prep for class, setup | C14: 0.25 | D14: =SUMIF(_xlfn._TRO_ALL(A:A), A14,_xlfn._TRO_ALL( C:C)) -> 8
A15: 45995 | B15: General admin | C15: 0.75
A16: 45995 | B16: Teaching | C16: 6
A17: 45995 | B17: Student feedback | C17: 1
A18: 45996 | B18: General admin | C18: 0.25 | D18: =SUMIF(_xlfn._TRO_ALL(A:A), A18,_xlfn._TRO_ALL( C:C)) -> 8
A19: 45996 | B19: 1:1 with Hannah | C19: 0.5
A20: 45996 | B20: Student feedback | C20: 5.5
A21: 45996 | B21: Feedback process improvement for workbook | C21: 1.75
A22: 45999 | B22: General admin | C22: 0.25 | D22: =SUMIF(_xlfn._TRO_ALL(A:A), A22,_xlfn._TRO_ALL( C:C)) -> 8 | E22: {=SUM(_xlfn.MAP(A2:INDEX(A:A, COUNTA(A:A)), C2:INDEX(C:C, COUNTA(C:C)), _xlfn.LAMBDA(_xlpm.a,_xlpm.b, IF(WEEKNUM(_xlpm.a)=WEEKNUM(A22), _xlpm.b, 0))))} -> 16
A23: 45999 | B23: Prep for class, setup | C23: 0.5
A24: 45999 | B24: Prep MFS OTLA | C24: 0.25
A25: 45999 | B25: Teaching | C25: 6
A26: 45999 | B26: Student feedback | C26: 1
A27: 46000 | B27: Prep for class, setup | C27: 0.5 | D27: =SUMIF(_xlfn._TRO_ALL(A:A), A27,_xlfn._TRO_ALL( C:C)) -> 8
A28: 46000 | B28: General admin | C28: 0.25
A29: 46000 | B29: Teaching | C29: 6
A30: 46000 | B30: Christmas team meeting | C30: 0.5
A31: 46000 | B31: Student feedback | C31: 0.75

Sheet AET
A1: AET Task | B1: Status | D1: Status options
A2: Essay | B2: Started | D2: Started
A3: Explain the teaching role and responsibilities in education and training | B3: Done | D3: First draft done
A4: Explain how the teaching role involves working with other professionals | B4: Done | D4: Reviewing
A5: Explain the boundaries between the teaching role and other professional roles | B5: Done | D5: Done
A6: Summarise key aspects of legislation, regulatory requirements and codes of practice relating to own role and responsibilities. | B6: Done
A7: Explain ways to promote equality and value diversity | B7: Done
A8: Explain why it is important to identify and meet individual learner needs | B8: Done | D8: Total tasks | E8: =COUNTA(A2:A45) - 3 -> 37
A9: Describe points of referral to meet the individual needs of learners | B9: Done | D9: First draft done | E9: =COUNTIF(B2:B37, "First draft done") -> 0 | F9: =E9/E8 -> 0
A10: Describe features of inclusive teaching and learning | B10: Done | D10: Not started | E10: =COUNTBLANK(B2:B37) -> 6 | F10: =E10/E8 -> 0.16216216
A11: Explain why it is important to create an inclusive teaching and learning environment | B11: Done | D11: Essay tasks | E11: =COUNTA(A3:A29) -> 27
A12: Explain ways to maintain a safe and supportive learning environment | B12: Done | D12: Essay first draft done | E12: =COUNTIF($B$3:$B$29, "First draft done") -> 0 | F12: =E12/E11 -> 0
A13: Explain why it is important to promote appropriate behaviour and respect for others | B13: Done | D13: Essay done | E13: =COUNTIF($B$3:$B$29, "Done") -> 27 | F13: =E13/E11 -> 1
A14: Explain ways to engage and motivate learners | B14: Done
A15: Summarise ways to establish ground rules with learner | B15: Done
A16: Explain why it is important to provide opportunities for learners to develop their English, mathematics, ICT and wider skills | B16: Done
A17: Compare the strengths and limitations of teaching and learning approaches used in own area of specialism and explain how they can meet individual learner needs | B17: Done
A18: Explain why it is important to select teaching and learning approaches, resources and assessment methods to meet individual leaner needs | B18: Done
A19: Explain the purpose of types of assessment used in education and training including initial, formative and summative | B19: Done
A20: Describe characteristics of different methods of assessment in education and training. (At least 3 different assessment methods) | B20: Done
A21: Compare the strengths and limitations of different assessment methods and Explain how these can be adapted in relation to meeting individual learner needs | B21: Done
A22: Explain why it is important to involve learners and others in the assessment process | B22: Done
A23: Explain the role and use of peer and self-assessment in the assessment process. | B23: Done
A24: Identify sources of information that should be made available to learners and others involved in the assessment process | B24: Done
A25: Describe the key features of constructive feedback | B25: Done
... A29: Summarise the requirements for keeping records of assessment in an organisation | B29: Done
A30: Microteach
A31: Devise an inclusive teaching and learning plan | B31: Done
A32: Justify own selection of teaching and learning approaches, resources and assessment methods in relation to meeting individual learner needs | B32: Done
A33: Use teaching and learning approaches, resources and assessment methods to meet individual learner needs
A34: Communicate with learners in ways that meet their individual needs
A35: Provide constructive feedback to learners to meet their individual needs
A36: Review the effectiveness of own delivery of inclusive teaching and learning
A37: Identify areas for improvement in own delivery of inclusive
A38: General tasks
A39: Check if links contains traces of ChatGPT | B39: Done
A40: Import files in Padlet | B40: Done
A41: Practice microteach

Sheet Student Feedback
A1: Year | B1: Week number | C1: Start date | D1: Teaching week | E1: Week/module number | F1: Group type | G1: Feedback process | H1: Student feedback | I1: Weekly hours | J1: Number of students | K1: Number of workbooks | L1: Time per student (min) | N1: Average time by learner by week
A2: 2025 | B2: {=_xlfn.LET( _xlpm.may_data, May!$A$2:INDEX(May!A:A, COUNTA(May!A:A)), _xlpm.june_data, June!$A$2:INDEX(June!A:A, COUNTA(June!A:A)), _xlpm.july_data, July!$A$2:INDEX(July!A:A, COUNTA(July!A:A)), _xlpm.august_data, August!$A$2:INDEX(August!A:A, COUNTA(August!A:A)), _xlpm.september_data, September!$A$2:INDEX(September!A:A, COUNTA(September!A:A)), _xlpm.october_data, October!$A$2:INDEX(October!A:A, COUNTA(October!A:A)), _xlpm.november_data, November!$A$2:INDEX(November!A:A, COUNTA(November!A:A)), _xlpm.december_data, December!$A$2:INDEX(December!A:A, COUNTA(December!A:A)), _xlpm.all_data, _xlfn.VSTACK(_xlpm.may_data, _xlpm.june_data, _xlpm.july_data, _xlpm.august_data, _xlpm.september_data, _xlpm.october_data, _xlpm.november_data, _xlpm.december_data), _xlpm.all_week_numbers, _xlfn.MAP(_xlpm.all_data, _xlfn.LAMBDA(_xlpm.a, WEEKNUM(_xlpm.a, 2))), _xlfn.UNIQUE(_xlpm.all_week_numbers))} -> 21 | C2: =DATE(A2,1,1) - WEEKDAY(DATE(A2,1,1),2) + 1 + 7*(B2-1) -> 45796 | D2: 0 | E2: 0 | F2: None | G2: {=_xlfn.LET( _xlpm.may_data, May!$A$2:INDEX(May!C:C, COUNTA(May!A:A)), _xlpm.june_data, June!$A$2:INDEX(June!C:C, COUNTA(June!A:A)), _xlpm.july_data, July!$A$2:INDEX(July!C:C, COUNTA(July!A:A)), _xlpm.august_data, August!$A$2:INDEX(August!C:C, COUNTA(August!A:A)), _xlpm.september_data, September!$A$2:INDEX(September!C:C, COUNTA(September!A:A)), _xlpm.october_data, October!$A$2:INDEX(October!C:C, COUNTA(October!A:A)), _xlpm.november_data, November!$A$2:INDEX(November!C:C, COUNTA(November!A:A)), _xlpm.december_data, December!$A$2:INDEX(December!C:C, COUNTA(December!A:A)), _xlpm.all_data, _xlfn.VSTACK(_xlpm.may_data, _xlpm.june_data, _xlpm.july_data, _xlpm.august_data, _xlpm.september_data, _xlpm.october_data, _xlpm.november_data, _xlpm.december_data), _xlpm.target_week, B2, SUM( _xlfn.BYROW( _xlpm.all_data, _xlfn.LAMBDA(_xlpm.row, IF( COUNTA(_xlpm.row) >= 3, IF( AND( WEEKNUM(INDEX(_xlpm.row,1),2) = _xlpm.target_week, ISNUMBER(SEARCH("feedback process", INDEX(_xlpm.row,2)&"")) ), INDEX(_xlpm.row,3), 0 ), 0 ) ) ) ) )} -> 0 | H2: {=_xlfn.LET( _xlpm.may_data, May!$A$2:INDEX(May!C:C, COUNTA(May!A:A)), _xlpm.june_data, June!$A$2:INDEX(June!C:C, COUNTA(June!A:A)), _xlpm.july_data, July!$A$2:INDEX(July!C:C, COUNTA(July!A:A)), _xlpm.august_data, August!$A$2:INDEX(August!C:C, COUNTA(August!A:A)), _xlpm.september_data, September!$A$2:INDEX(September!C:C, COUNTA(September!A:A)), _xlpm.october_data, October!$A$2:INDEX(October!C:C, COUNTA(October!A:A)), _xlpm.november_data, November!$A$2:INDEX(November!C:C, COUNTA(November!A:A)), _xlpm.december_data, December!$A$2:INDEX(December!C:C, COUNTA(December!A:A)), _xlpm.all_data, _xlfn.VSTACK(_xlpm.may_data, _xlpm.june_data, _xlpm.july_data, _xlpm.august_data, _xlpm.september_data, _xlpm.october_data, _xlpm.november_data, _xlpm.december_data), _xlpm.target_week, B2, SUM( _xlfn.BYROW( _xlpm.all_data, _xlfn.LAMBDA(_xlpm.row, IF( COUNTA(_xlpm.row) >= 3, IF( AND( WEEKNUM(INDEX(_xlpm.row,1),2) = _xlpm.target_week, ISNUMBER(SEARCH("student feedback", INDEX(_xlpm.row,2)&"")) ), INDEX(_xlpm.row,3), 0 ), 0 ) ) ) ) )} -> 0 | I2: {=_xlfn.LET( _xlpm.may_data, May!$A$2:INDEX(May!C:C, COUNTA(May!A:A)), _xlpm.june_data, June!$A$2:INDEX(June!C:C, COUNTA(June!A:A)), _xlpm.july_data, July!$A$2:INDEX(July!C:C, COUNTA(July!A:A)), _xlpm.august_data, August!$A$2:INDEX(August!C:C, COUNTA(August!A:A)), _xlpm.september_data, September!$A$2:INDEX(September!C:C, COUNTA(September!A:A)), _xlpm.october_data, October!$A$2:INDEX(October!C:C, COUNTA(October!A:A)), _xlpm.november_data, November!$A$2:INDEX(November!C:C, COUNTA(November!A:A)), _xlpm.december_data, December!$A$2:INDEX(December!C:C, COUNTA(December!A:A)), _xlpm.all_data, _xlfn.VSTACK(_xlpm.may_data, _xlpm.june_data, _xlpm.july_data, _xlpm.august_data, _xlpm.september_data, _xlpm.october_data, _xlpm.november_data, _xlpm.december_data), _xlpm.target_week, B2, SUM( _xlfn.BYROW( _xlpm.all_data, _xlfn.LAMBDA(_xlpm.row, IF( COUNTA(_xlpm.row) >= 3, IF( AND( WEEKNUM(INDEX(_xlpm.row,1),2) = _xlpm.target_week, ISNUMBER(SEARCH("feedback", INDEX(_xlpm.row,2)&"")) ), INDEX(_xlpm.row,3), 0 ), 0 ) ) ) ) )} -> 0 | J2: 0 | K2: 0 | L2: =IFERROR(H2/J2 * 60, 0) -> 0 | N2: =AVERAGEIF(L2:L33, ">0") -> 25.514373
A3: 2025 | B3: 22 | C3: =DATE(A3,1,1) - WEEKDAY(DATE(A3,1,1),2) + 1 + 7*(B3-1) -> 45803 | D3: 0 | E3: 0 | F3: None | G3: {=_xlfn.LET( _xlpm.may_data, May!$A$2:INDEX(May!C:C, COUNTA(May!A:A)), _xlpm.june_data, June!$A$2:INDEX(June!C:C, COUNTA(June!A:A)), _xlpm.july_data, July!$A$2:INDEX(July!C:C, COUNTA(July!A:A)), _xlpm.august_data, August!$A$2:INDEX(August!C:C, COUNTA(August!A:A)), _xlpm.september_data, September!$A$2:INDEX(September!C:C, COUNTA(September!A:A)), _xlpm.october_data, October!$A$2:INDEX(October!C:C, COUNTA(October!A:A)), _xlpm.november_data, November!$A$2:INDEX(November!C:C, COUNTA(November!A:A)), _xlpm.december_data, December!$A$2:INDEX(December!C:C, COUNTA(December!A:A)), _xlpm.all_data, _xlfn.VSTACK(_xlpm.may_data, _xlpm.june_data, _xlpm.july_data, _xlpm.august_data, _xlpm.september_data, _xlpm.october_data, _xlpm.november_data, _xlpm.december_data), _xlpm.target_week, B3, SUM( _xlfn.BYROW( _xlpm.all_data, _xlfn.LAMBDA(_xlpm.row, IF( COUNTA(_xlpm.row) >= 3, IF( AND( WEEKNUM(INDEX(_xlpm.row,1),2) = _xlpm.target_week, ISNUMBER(SEARCH("feedback process", INDEX(_xlpm.row,2)&"")) ), INDEX(_xlpm.row,3), 0 ), 0 ) ) ) ) )} -> 0 | H3: {=_xlfn.LET( _xlpm.may_data, May!$A$2:INDEX(May!C:C, COUNTA(May!A:A)), _xlpm.june_data, June!$A$2:INDEX(June!C:C, COUNTA(June!A:A)), _xlpm.july_data, July!$A$2:INDEX(July!C:C, COUNTA(July!A:A)), _xlpm.august_data, August!$A$2:INDEX(August!C:C, COUNTA(August!A:A)), _xlpm.september_data, September!$A$2:INDEX(September!C:C, COUNTA(September!A:A)), _xlpm.october_data, October!$A$2:INDEX(October!C:C, COUNTA(October!A:A)), _xlpm.november_data, November!$A$2:INDEX(November!C:C, COUNTA(November!A:A)), _xlpm.december_data, December!$A$2:INDEX(December!C:C, COUNTA(December!A:A)), _xlpm.all_data, _xlfn.VSTACK(_xlpm.may_data, _xlpm.june_data, _xlpm.july_data, _xlpm.august_data, _xlpm.september_data, _xlpm.october_data, _xlpm.november_data, _xlpm.december_data), _xlpm.target_week, B3, SUM( _xlfn.BYROW( _xlpm.all_data, _xlfn.LAMBDA(_xlpm.row, IF( COUNTA(_xlpm.row) >= 3, IF( AND( WEEKNUM(INDEX(_xlpm.row,1),2) = _xlpm.target_week, ISNUMBER(SEARCH("student feedback", INDEX(_xlpm.row,2)&"")) ), INDEX(_xlpm.row,3), 0 ), 0 ) ) ) ) )} -> 0 | I3: {=_xlfn.LET( _xlpm.may_data, May!$A$2:INDEX(May!C:C, COUNTA(May!A:A)), _xlpm.june_data, June!$A$2:INDEX(June!C:C, COUNTA(June!A:A)), _xlpm.july_data, July!$A$2:INDEX(July!C:C, COUNTA(July!A:A)), _xlpm.august_data, August!$A$2:INDEX(August!C:C, COUNTA(August!A:A)), _xlpm.september_data, September!$A$2:INDEX(September!C:C, COUNTA(September!A:A)), _xlpm.october_data, October!$A$2:INDEX(October!C:C, COUNTA(October!A:A)), _xlpm.november_data, November!$A$2:INDEX(November!C:C, COUNTA(November!A:A)), _xlpm.december_data, December!$A$2:INDEX(December!C:C, COUNTA(December!A:A)), _xlpm.all_data, _xlfn.VSTACK(_xlpm.may_data, _xlpm.june_data, _xlpm.july_data, _xlpm.august_data, _xlpm.september_data, _xlpm.october_data, _xlpm.november_data, _xlpm.december_data), _xlpm.target_week, B3, SUM( _xlfn.BYROW( _xlpm.all_data, _xlfn.LAMBDA(_xlpm.row, IF( COUNTA(_xlpm.row) >= 3, IF( AND( WEEKNUM(INDEX(_xlpm.row,1),2) = _xlpm.target_week, ISNUMBER(SEARCH("feedback", INDEX(_xlpm.row,2)&"")) ), INDEX(_xlpm.row,3), 0 ), 0 ) ) ) ) )} -> 0 | J3: 0 | K3: 0 | L3: =IFERROR(H3/J3 * 60, 0) -> 0
A4: 2025 | B4: 23 | C4: =DATE(A4,1,1) - WEEKDAY(DATE(A4,1,1),2) + 1 + 7*(B4-1) -> 45810 | D4: 0 | E4: 0 | F4: None | G4: {=_xlfn.LET( _xlpm.may_data, May!$A$2:INDEX(May!C:C, COUNTA(May!A:A)), _xlpm.june_data, June!$A$2:INDEX(June!C:C, COUNTA(June!A:A)), _xlpm.july_data, July!$A$2:INDEX(July!C:C, COUNTA(July!A:A)), _xlpm.august_data, August!$A$2:INDEX(August!C:C, COUNTA(August!A:A)), _xlpm.september_data, September!$A$2:INDEX(September!C:C, COUNTA(September!A:A)), _xlpm.october_data, October!$A$2:INDEX(October!C:C, COUNTA(October!A:A)), _xlpm.november_data, November!$A$2:INDEX(November!C:C, COUNTA(November!A:A)), _xlpm.december_data, December!$A$2:INDEX(December!C:C, COUNTA(December!A:A)), _xlpm.all_data, _xlfn.VSTACK(_xlpm.may_data, _xlpm.june_data, _xlpm.july_data, _xlpm.august_data, _xlpm.september_data, _xlpm.october_data, _xlpm.november_data, _xlpm.december_data), _xlpm.target_week, B4, SUM( _xlfn.BYROW( _xlpm.all_data, _xlfn.LAMBDA(_xlpm.row, IF( COUNTA(_xlpm.row) >= 3, IF( AND( WEEKNUM(INDEX(_xlpm.row,1),2) = _xlpm.target_week, ISNUMBER(SEARCH("feedback process", INDEX(_xlpm.row,2)&"")) ), INDEX(_xlpm.row,3), 0 ), 0 ) ) ) ) )} -> 0 | H4: {=_xlfn.LET( _xlpm.may_data, May!$A$2:INDEX(May!C:C, COUNTA(May!A:A)), _xlpm.june_data, June!$A$2:INDEX(June!C:C, COUNTA(June!A:A)), _xlpm.july_data, July!$A$2:INDEX(July!C:C, COUNTA(July!A:A)), _xlpm.august_data, August!$A$2:INDEX(August!C:C, COUNTA(August!A:A)), _xlpm.september_data, September!$A$2:INDEX(September!C:C, COUNTA(September!A:A)), _xlpm.october_data, October!$A$2:INDEX(October!C:C, COUNTA(October!A:A)), _xlpm.november_data, November!$A$2:INDEX(November!C:C, COUNTA(November!A:A)), _xlpm.december_data, December!$A$2:INDEX(December!C:C, COUNTA(December!A:A)), _xlpm.all_data, _xlfn.VSTACK(_xlpm.may_data, _xlpm.june_data, _xlpm.july_data, _xlpm.august_data, _xlpm.september_data, _xlpm.october_data, _xlpm.november_data, _xlpm.december_data), _xlpm.target_week, B4, SUM( _xlfn.BYROW( _xlpm.all_data, _xlfn.LAMBDA(_xlpm.row, IF( COUNTA(_xlpm.row) >= 3, IF( AND( WEEKNUM(INDEX(_xlpm.row,1),2) = _xlpm.target_week, ISNUMBER(SEARCH("student feedback", INDEX(_xlpm.row,2)&"")) ), INDEX(_xlpm.row,3), 0 ), 0 ) ) ) ) )} -> 0 | I4: {=_xlfn.LET( _xlpm.may_data, May!$A$2:INDEX(May!C:C, COUNTA(May!A:A)), _xlpm.june_data, June!$A$2:INDEX(June!C:C, COUNTA(June!A:A)), _xlpm.july_data, July!$A$2:INDEX(July!C:C, COUNTA(July!A:A)), _xlpm.august_data, August!$A$2:INDEX(August!C:C, COUNTA(August!A:A)), _xlpm.september_data, September!$A$2:INDEX(September!C:C, COUNTA(September!A:A)), _xlpm.october_data, October!$A$2:INDEX(October!C:C, COUNTA(October!A:A)), _xlpm.november_data, November!$A$2:INDEX(November!C:C, COUNTA(November!A:A)), _xlpm.december_data, December!$A$2:INDEX(December!C:C, COUNTA(December!A:A)), _xlpm.all_data, _xlfn.VSTACK(_xlpm.may_data, _xlpm.june_data, _xlpm.july_data, _xlpm.august_data, _xlpm.september_data, _xlpm.october_data, _xlpm.november_data, _xlpm.december_data), _xlpm.target_week, B4, SUM( _xlfn.BYROW( _xlpm.all_data, _xlfn.LAMBDA(_xlpm.row, IF( COUNTA(_xlpm.row) >= 3, IF( AND( WEEKNUM(INDEX(_xlpm.row,1),2) = _xlpm.target_week, ISNUMBER(SEARCH("feedback", INDEX(_xlpm.row,2)&"")) ), INDEX(_xlpm.row,3), 0 ), 0 ) ) ) ) )} -> 0 | J4: 0 | K4: 0 | L4: =IFERROR(H4/J4 * 60, 0) -> 0
A5: 2025 | B5: 24 | C5: =DATE(A5,1,1) - WEEKDAY(DATE(A5,1,1),2) + 1 + 7*(B5-1) -> 45817 | D5: 1 | E5: 1 | F5: Bootcamp | G5: {=_xlfn.LET( _xlpm.may_data, May!$A$2:INDEX(May!C:C, COUNTA(May!A:A)), _xlpm.june_data, June!$A$2:INDEX(June!C:C, COUNTA(June!A:A)), _xlpm.july_data, July!$A$2:INDEX(July!C:C, COUNTA(July!A:A)), _xlpm.august_data, August!$A$2:INDEX(August!C:C, COUNTA(August!A:A)), _xlpm.september_data, September!$A$2:INDEX(September!C:C, COUNTA(September!A:A)), _xlpm.october_data, October!$A$2:INDEX(October!C:C, COUNTA(October!A:A)), _xlpm.november_data, November!$A$2:INDEX(November!C:C, COUNTA(November!A:A)), _xlpm.december_data, December!$A$2:INDEX(December!C:C, COUNTA(December!A:A)), _xlpm.all_data, _xlfn.VSTACK(_xlpm.may_data, _xlpm.june_data, _xlpm.july_data, _xlpm.august_data, _xlpm.september_data, _xlpm.october_data, _xlpm.november_data, _xlpm.december_data), _xlpm.target_week, B5, SUM( _xlfn.BYROW( _xlpm.all_data, _xlfn.LAMBDA(_xlpm.row, IF( COUNTA(_xlpm.row) >= 3, IF( AND( WEEKNUM(INDEX(_xlpm.row,1),2) = _xlpm.target_week, ISNUMBER(SEARCH("feedback process", INDEX(_xlpm.row,2)&"")) ), INDEX(_xlpm.row,3), 0 ), 0 ) ) ) ) )} -> 1.25 | H5: {=_xlfn.LET( _xlpm.may_data, May!$A$2:INDEX(May!C:C, COUNTA(May!A:A)), _xlpm.june_data, June!$A$2:INDEX(June!C:C, COUNTA(June!A:A)), _xlpm.july_data, July!$A$2:INDEX(July!C:C, COUNTA(July!A:A)), _xlpm.august_data, August!$A$2:INDEX(August!C:C, COUNTA(August!A:A)), _xlpm.september_data, September!$A$2:INDEX(September!C:C, COUNTA(September!A:A)), _xlpm.october_data, October!$A$2:INDEX(October!C:C, COUNTA(October!A:A)), _xlpm.november_data, November!$A$2:INDEX(November!C:C, COUNTA(November!A:A)), _xlpm.december_data, December!$A$2:INDEX(December!C:C, COUNTA(December!A:A)), _xlpm.all_data, _xlfn.VSTACK(_xlpm.may_data, _xlpm.june_data, _xlpm.july_data, _xlpm.august_data, _xlpm.september_data, _xlpm.october_data, _xlpm.november_data, _xlpm.december_data), _xlpm.target_week, B5, SUM( _xlfn.BYROW( _xlpm.all_data, _xlfn.LAMBDA(_xlpm.row, IF( COUNTA(_xlpm.row) >= 3, IF( AND( WEEKNUM(INDEX(_xlpm.row,1),2) = _xlpm.target_week, ISNUMBER(SEARCH("student feedback", INDEX(_xlpm.row,2)&"")) ), INDEX(_xlpm.row,3), 0 ), 0 ) ) ) ) )} -> 5 | I5: {=_xlfn.LET( _xlpm.may_data, May!$A$2:INDEX(May!C:C, COUNTA(May!A:A)), _xlpm.june_data, June!$A$2:INDEX(June!C:C, COUNTA(June!A:A)), _xlpm.july_data, July!$A$2:INDEX(July!C:C, COUNTA(July!A:A)), _xlpm.august_data, August!$A$2:INDEX(August!C:C, COUNTA(August!A:A)), _xlpm.september_data, September!$A$2:INDEX(September!C:C, COUNTA(September!A:A)), _xlpm.october_data, October!$A$2:INDEX(October!C:C, COUNTA(October!A:A)), _xlpm.november_data, November!$A$2:INDEX(November!C:C, COUNTA(November!A:A)), _xlpm.december_data, December!$A$2:INDEX(December!C:C, COUNTA(December!A:A)), _xlpm.all_data, _xlfn.VSTACK(_xlpm.may_data, _xlpm.june_data, _xlpm.july_data, _xlpm.august_data, _xlpm.september_data, _xlpm.october_data, _xlpm.november_data, _xlpm.december_data), _xlpm.target_week, B5, SUM( _xlfn.BYROW( _xlpm.all_data, _xlfn.LAMBDA(_xlpm.row, IF( COUNTA(_xlpm.row) >= 3, IF( AND( WEEKNUM(INDEX(_xlpm.row,1),2) = _xlpm.target_week, ISNUMBER(SEARCH("feedback", INDEX(_xlpm.row,2)&"")) ), INDEX(_xlpm.row,3), 0 ), 0 ) ) ) ) )} -> 6.25 | J5: 9 | K5: 0 | L5: =IFERROR(H5/J5 * 60, 0) -> 33.333333
A6: 2025 | B6: 25 | C6: =DATE(A6,1,1) - WEEKDAY(DATE(A6,1,1),2) + 1 + 7*(B6-1) -> 45824 | D6: 1 | E6: 2 | F6: Bootcamp | G6: {=_xlfn.LET( _xlpm.may_data, May!$A$2:INDEX(May!C:C, COUNTA(May!A:A)), _xlpm.june_data, June!$A$2:INDEX(June!C:C, COUNTA(June!A:A)), _xlpm.july_data, July!$A$2:INDEX(July!C:C, COUNTA(July!A:A)), _xlpm.august_data, August!$A$2:INDEX(August!C:C, COUNTA(August!A:A)), _xlpm.september_data, September!$A$2:INDEX(September!C:C, COUNTA(September!A:A)), _xlpm.october_data, October!$A$2:INDEX(October!C:C, COUNTA(October!A:A)), _xlpm.november_data, November!$A$2:INDEX(November!C:C, COUNTA(November!A:A)), _xlpm.december_data, December!$A$2:INDEX(December!C:C, COUNTA(December!A:A)), _xlpm.all_data, _xlfn.VSTACK(_xlpm.may_data, _xlpm.june_data, _xlpm.july_data, _xlpm.august_data, _xlpm.september_data, _xlpm.october_data, _xlpm.november_data, _xlpm.december_data), _xlpm.target_week, B6, SUM( _xlfn.BYROW( _xlpm.all_data, _xlfn.LAMBDA(_xlpm.row, IF( COUNTA(_xlpm.row) >= 3, IF( AND( WEEKNUM(INDEX(_xlpm.row,1),2) = _xlpm.target_week, ISNUMBER(SEARCH("feedback process", INDEX(_xlpm.row,2)&"")) ), INDEX(_xlpm.row,3), 0 ), 0 ) ) ) ) )} -> 5.75 | H6: {=_xlfn.LET( _xlpm.may_data, May!$A$2:INDEX(May!C:C, COUNTA(May!A:A)), _xlpm.june_data, June!$A$2:INDEX(June!C:C, COUNTA(June!A:A)), _xlpm.july_data, July!$A$2:INDEX(July!C:C, COUNTA(July!A:A)), _xlpm.august_data, August!$A$2:INDEX(August!C:C, COUNTA(August!A:A)), _xlpm.september_data, September!$A$2:INDEX(September!C:C, COUNTA(September!A:A)), _xlpm.october_data, October!$A$2:INDEX(October!C:C, COUNTA(October!A:A)), _xlpm.november_data, November!$A$2:INDEX(November!C:C, COUNTA(November!A:A)), _xlpm.december_data, December!$A$2:INDEX(December!C:C, COUNTA(December!A:A)), _xlpm.all_data, _xlfn.VSTACK(_xlpm.may_data, _xlpm.june_data, _xlpm.july_data, _xlpm.august_data, _xlpm.september_data, _xlpm.october_data, _xlpm.november_data, _xlpm.december_data), _xlpm.target_week, B6, SUM( _xlfn.BYROW( _xlpm.all_data, _xlfn.LAMBDA(_xlpm.row, IF( COUNTA(_xlpm.row) >= 3, IF( AND( WEEKNUM(INDEX(_xlpm.row,1),2) = _xlpm.target_week, ISNUMBER(SEARCH("student feedback", INDEX(_xlpm.row,2)&"")) ), INDEX(_xlpm.row,3), 0 ), 0 ) ) ) ) )} -> 4 | I6: {=_xlfn.LET( _xlpm.may_data, May!$A$2:INDEX(May!C:C, COUNTA(May!A:A)), _xlpm.june_data, June!$A$2:INDEX(June!C:C, COUNTA(June!A:A)), _xlpm.july_data, July!$A$2:INDEX(July!C:C, COUNTA(July!A:A)), _xlpm.august_data, August!$A$2:INDEX(August!C:C, COUNTA(August!A:A)), _xlpm.september_data, September!$A$2:INDEX(September!C:C, COUNTA(September!A:A)), _xlpm.october_data, October!$A$2:INDEX(October!C:C, COUNTA(October!A:A)), _xlpm.november_data, November!$A$2:INDEX(November!C:C, COUNTA(November!A:A)), _xlpm.december_data, December!$A$2:INDEX(December!C:C, COUNTA(December!A:A)), _xlpm.all_data, _xlfn.VSTACK(_xlpm.may_data, _xlpm.june_data, _xlpm.july_data, _xlpm.august_data, _xlpm.september_data, _xlpm.october_data, _xlpm.november_data, _xlpm.december_data), _xlpm.target_week, B6, SUM( _xlfn.BYROW( _xlpm.all_data, _xlfn.LAMBDA(_xlpm.row, IF( COUNTA(_xlpm.row) >= 3, IF( AND( WEEKNUM(INDEX(_xlpm.row,1),2) = _xlpm.target_week, ISNUMBER(SEARCH("feedback", INDEX(_xlpm.row,2)&"")) ), INDEX(_xlpm.row,3), 0 ), 0 ) ) ) ) )} -> 10.25 | J6: 7 | K6: 0 | L6: =IFERROR(H6/J6 * 60, 0) -> 34.285714
A7: 2025 | B7: 26 | C7: =DATE(A7,1,1) - WEEKDAY(DATE(A7,1,1),2) + 1 + 7*(B7-1) -> 45831 | D7: 1 | E7: 3 | F7: Bootcamp | G7: {=_xlfn.LET( _xlpm.may_data, May!$A$2:INDEX(May!C:C, COUNTA(May!A:A)), _xlpm.june_data, June!$A$2:INDEX(June!C:C, COUNTA(June!A:A)), _xlpm.july_data, July!$A$2:INDEX(July!C:C, COUNTA(July!A:A)), _xlpm.august_data, August!$A$2:INDEX(August!C:C, COUNTA(August!A:A)), _xlpm.september_data, September!$A$2:INDEX(September!C:C, COUNTA(September!A:A)), _xlpm.october_data, October!$A$2:INDEX(October!C:C, COUNTA(October!A:A)), _xlpm.november_data, November!$A$2:INDEX(November!C:C, COUNTA(November!A:A)), _xlpm.december_data, December!$A$2:INDEX(December!C:C, COUNTA(December!A:A)), _xlpm.all_data, _xlfn.VSTACK(_xlpm.may_data, _xlpm.june_data, _xlpm.july_data, _xlpm.august_data, _xlpm.september_data, _xlpm.october_data, _xlpm.november_data, _xlpm.december_data), _xlpm.target_week, B7, SUM( _xlfn.BYROW( _xlpm.all_data, _xlfn.LAMBDA(_xlpm.row, IF( COUNTA(_xlpm.row) >= 3, IF( AND( WEEKNUM(INDEX(_xlpm.row,1),2) = _xlpm.target_week, ISNUMBER(SEARCH("feedback process", INDEX(_xlpm.row,2)&"")) ), INDEX(_xlpm.row,3), 0 ), 0 ) ) ) ) )} -> 0 | H7: {=_xlfn.LET( _xlpm.may_data, May!$A$2:INDEX(May!C:C, COUNTA(May!A:A)), _xlpm.june_data, June!$A$2:INDEX(June!C:C, COUNTA(June!A:A)), _xlpm.july_data, July!$A$2:INDEX(July!C:C, COUNTA(July!A:A)), _xlpm.august_data, August!$A$2:INDEX(August!C:C, COUNTA(August!A:A)), _xlpm.september_data, September!$A$2:INDEX(September!C:C, COUNTA(September!A:A)), _xlpm.october_data, October!$A$2:INDEX(October!C:C, COUNTA(October!A:A)), _xlpm.november_data, November!$A$2:INDEX(November!C:C, COUNTA(November!A:A)), _xlpm.december_data, December!$A$2:INDEX(December!C:C, COUNTA(December!A:A)), _xlpm.all_data, _xlfn.VSTACK(_xlpm.may_data, _xlpm.june_data, _xlpm.july_data, _xlpm.august_data, _xlpm.september_data, _xlpm.october_data, _xlpm.november_data, _xlpm.december_data), _xlpm.target_week, B7, SUM( _xlfn.BYROW( _xlpm.all_data, _xlfn.LAMBDA(_xlpm.row, IF( COUNTA(_xlpm.row) >= 3, IF( AND( WEEKNUM(INDEX(_xlpm.row,1),2) = _xlpm.target_week, ISNUMBER(SEARCH("student feedback", INDEX(_xlpm.row,2)&"")) ), INDEX(_xlpm.row,3), 0 ), 0 ) ) ) ) )} -> 11 | I7: {=_xlfn.LET( _xlpm.may_data, May!$A$2:INDEX(May!C:C, COUNTA(May!A:A)), _xlpm.june_data, June!$A$2:INDEX(June!C:C, COUNTA(June!A:A)), _xlpm.july_data, July!$A$2:INDEX(July!C:C, COUNTA(July!A:A)), _xlpm.august_data, August!$A$2:INDEX(August!C:C, COUNTA(August!A:A)), _xlpm.september_data, September!$A$2:INDEX(September!C:C, COUNTA(September!A:A)), _xlpm.october_data, October!$A$2:INDEX(October!C:C, COUNTA(October!A:A)), _xlpm.november_data, November!$A$2:INDEX(November!C:C, COUNTA(November!A:A)), _xlpm.december_data, December!$A$2:INDEX(December!C:C, COUNTA(December!A:A)), _xlpm.all_data, _xlfn.VSTACK(_xlpm.may_data, _xlpm.june_data, _xlpm.july_data, _xlpm.august_data, _xlpm.september_data, _xlpm.october_data, _xlpm.november_data, _xlpm.december_data), _xlpm.target_week, B7, SUM( _xlfn.BYROW( _xlpm.all_data, _xlfn.LAMBDA(_xlpm.row, IF( COUNTA(_xlpm.row) >= 3, IF( AND( WEEKNUM(INDEX(_xlpm.row,1),2) = _xlpm.target_week, ISNUMBER(SEARCH("feedback", INDEX(_xlpm.row,2)&"")) ), INDEX(_xlpm.row,3), 0 ), 0 ) ) ) ) )} -> 11.5 | J7: 7 | K7: 0 | L7: =IFERROR(H7/J7 * 60, 0) -> 94.285714
A8: 2025 | B8: 27 | C8: =DATE(A8,1,1) - WEEKDAY(DATE(A8,1,1),2) + 1 + 7*(B8-1) -> 45838 | D8: 0 | E8: 0 | F8: None | G8: {=_xlfn.LET( _xlpm.may_data, May!$A$2:INDEX(May!C:C, COUNTA(May!A:A)), _xlpm.june_data, June!$A$2:INDEX(June!C:C, COUNTA(June!A:A)), _xlpm.july_data, July!$A$2:INDEX(July!C:C, COUNTA(July!A:A)), _xlpm.august_data, August!$A$2:INDEX(August!C:C, COUNTA(August!A:A)), _xlpm.september_data, September!$A$2:INDEX(September!C:C, COUNTA(September!A:A)), _xlpm.october_data, October!$A$2:INDEX(October!C:C, COUNTA(October!A:A)), _xlpm.november_data, November!$A$2:INDEX(November!C:C, COUNTA(November!A:A)), _xlpm.december_data, December!$A$2:INDEX(December!C:C, COUNTA(December!A:A)), _xlpm.all_data, _xlfn.VSTACK(_xlpm.may_data, _xlpm.june_data, _xlpm.july_data, _xlpm.august_data, _xlpm.september_data, _xlpm.october_data, _xlpm.november_data, _xlpm.december_data), _xlpm.target_week, B8, SUM( _xlfn.BYROW( _xlpm.all_data, _xlfn.LAMBDA(_xlpm.row, IF( COUNTA(_xlpm.row) >= 3, IF( AND( WEEKNUM(INDEX(_xlpm.row,1),2) = _xlpm.target_week, ISNUMBER(SEARCH("feedback process", INDEX(_xlpm.row,2)&"")) ), INDEX(_xlpm.row,3), 0 ), 0 ) ) ) ) )} -> 1.25 | H8: {=_xlfn.LET( _xlpm.may_data, May!$A$2:INDEX(May!C:C, COUNTA(May!A:A)), _xlpm.june_data, June!$A$2:INDEX(June!C:C, COUNTA(June!A:A)), _xlpm.july_data, July!$A$2:INDEX(July!C:C, COUNTA(July!A:A)), _xlpm.august_data, August!$A$2:INDEX(August!C:C, COUNTA(August!A:A)), _xlpm.september_data, September!$A$2:INDEX(September!C:C, COUNTA(September!A:A)), _xlpm.october_data, October!$A$2:INDEX(October!C:C, COUNTA(October!A:A)), _xlpm.november_data, November!$A$2:INDEX(November!C:C, COUNTA(November!A:A)), _xlpm.december_data, December!$A$2:INDEX(December!C:C, COUNTA(December!A:A)), _xlpm.all_data, _xlfn.VSTACK(_xlpm.may_data, _xlpm.june_data, _xlpm.july_data, _xlpm.august_data, _xlpm.september_data, _xlpm.october_data, _xlpm.november_data, _xlpm.december_data), _xlpm.target_week, B8, SUM( _xlfn.BYROW( _xlpm.all_data, _xlfn.LAMBDA(_xlpm.row, IF( COUNTA(_xlpm.row) >= 3, IF( AND( WEEKNUM(INDEX(_xlpm.row,1),2) = _xlpm.target_week, ISNUMBER(SEARCH("student feedback", INDEX(_xlpm.row,2)&"")) ), INDEX(_xlpm.row,3), 0 ), 0 ) ) ) ) )} -> 0 | I8: {=_xlfn.LET( _xlpm.may_data, May!$A$2:INDEX(May!C:C, COUNTA(May!A:A)), _xlpm.june_data, June!$A$2:INDEX(June!C:C, COUNTA(June!A:A)), _xlpm.july_data, July!$A$2:INDEX(July!C:C, COUNTA(July!A:A)), _xlpm.august_data, August!$A$2:INDEX(August!C:C, COUNTA(August!A:A)), _xlpm.september_data, September!$A$2:INDEX(September!C:C, COUNTA(September!A:A)), _xlpm.october_data, October!$A$2:INDEX(October!C:C, COUNTA(October!A:A)), _xlpm.november_data, November!$A$2:INDEX(November!C:C, COUNTA(November!A:A)), _xlpm.december_data, December!$A$2:INDEX(December!C:C, COUNTA(December!A:A)), _xlpm.all_data, _xlfn.VSTACK(_xlpm.may_data, _xlpm.june_data, _xlpm.july_data, _xlpm.august_data, _xlpm.september_data, _xlpm.october_data, _xlpm.november_data, _xlpm.december_data), _xlpm.target_week, B8, SUM( _xlfn.BYROW( _xlpm.all_data, _xlfn.LAMBDA(_xlpm.row, IF( COUNTA(_xlpm.row) >= 3, IF( AND( WEEKNUM(INDEX(_xlpm.row,1),2) = _xlpm.target_week, ISNUMBER(SEARCH("feedback", INDEX(_xlpm.row,2)&"")) ), INDEX(_xlpm.row,3), 0 ), 0 ) ) ) ) )} -> 1.25 | J8: 7 | K8: 0 | L8: =IFERROR(H8/J8 * 60, 0) -> 0
A9: 2025 | B9: 28 | C9: =DATE(A9,1,1) - WEEKDAY(DATE(A9,1,1),2) + 1 + 7*(B9-1) -> 45845 | D9: 1 | E9: 5 | F9: Bootcamp | G9: {=_xlfn.LET( _xlpm.may_data, May!$A$2:INDEX(May!C:C, COUNTA(May!A:A)), _xlpm.june_data, June!$A$2:INDEX(June!C:C, COUNTA(June!A:A)), _xlpm.july_data, July!$A$2:INDEX(July!C:C, COUNTA(July!A:A)), _xlpm.august_data, August!$A$2:INDEX(August!C:C, COUNTA(August!A:A)), _xlpm.september_data, September!$A$2:INDEX(September!C:C, COUNTA(September!A:A)), _xlpm.october_data, October!$A$2:INDEX(October!C:C, COUNTA(October!A:A)), _xlpm.november_data, November!$A$2:INDEX(November!C:C, COUNTA(November!A:A)), _xlpm.december_data, December!$A$2:INDEX(December!C:C, COUNTA(December!A:A)), _xlpm.all_data, _xlfn.VSTACK(_xlpm.may_data, _xlpm.june_data, _xlpm.july_data, _xlpm.august_data, _xlpm.september_data, _xlpm.october_data, _xlpm.november_data, _xlpm.december_data), _xlpm.target_week, B9, SUM( _xlfn.BYROW( _xlpm.all_data, _xlfn.LAMBDA(_xlpm.row, IF( COUNTA(_xlpm.row) >= 3, IF( AND( WEEKNUM(INDEX(_xlpm.row,1),2) = _xlpm.target_week, ISNUMBER(SEARCH("feedback process", INDEX(_xlpm.row,2)&"")) ), INDEX(_xlpm.row,3), 0 ), 0 ) ) ) ) )} -> 0 | H9: {=_xlfn.LET( _xlpm.may_data, May!$A$2:INDEX(May!C:C, COUNTA(May!A:A)), _xlpm.june_data, June!$A$2:INDEX(June!C:C, COUNTA(June!A:A)), _xlpm.july_data, July!$A$2:INDEX(July!C:C, COUNTA(July!A:A)), _xlpm.august_data, August!$A$2:INDEX(August!C:C, COUNTA(August!A:A)), _xlpm.september_data, September!$A$2:INDEX(September!C:C, COUNTA(September!A:A)), _xlpm.october_data, October!$A$2:INDEX(October!C:C, COUNTA(October!A:A)), _xlpm.november_data, November!$A$2:INDEX(November!C:C, COUNTA(November!A:A)), _xlpm.december_data, December!$A$2:INDEX(December!C:C, COUNTA(December!A:A)), _xlpm.all_data, _xlfn.VSTACK(_xlpm.may_data, _xlpm.june_data, _xlpm.july_data, _xlpm.august_data, _xlpm.september_data, _xlpm.october_data, _xlpm.november_data, _xlpm.december_data), _xlpm.target_week, B9, SUM( _xlfn.BYROW( _xlpm.all_data, _xlfn.LAMBDA(_xlpm.row, IF( COUNTA(_xlpm.row) >= 3, IF( AND( WEEKNUM(INDEX(_xlpm.row,1),2) = _xlpm.target_week, ISNUMBER(SEARCH("student feedback", INDEX(_xlpm.row,2)&"")) ), INDEX(_xlpm.row,3), 0 ), 0 ) ) ) ) )} -> 5.5 | I9: {=_xlfn.LET( _xlpm.may_data, May!$A$2:INDEX(May!C:C, COUNTA(May!A:A)), _xlpm.june_data, June!$A$2:INDEX(June!C:C, COUNTA(June!A:A)), _xlpm.july_data, July!$A$2:INDEX(July!C:C, COUNTA(July!A:A)), _xlpm.august_data, August!$A$2:INDEX(August!C:C, COUNTA(August!A:A)), _xlpm.september_data, September!$A$2:INDEX(September!C:C, COUNTA(September!A:A)), _xlpm.october_data, October!$A$2:INDEX(October!C:C, COUNTA(October!A:A)), _xlpm.november_data, November!$A$2:INDEX(November!C:C, COUNTA(November!A:A)), _xlpm.december_data, December!$A$2:INDEX(December!C:C, COUNTA(December!A:A)), _xlpm.all_data, _xlfn.VSTACK(_xlpm.may_data, _xlpm.june_data, _xlpm.july_data, _xlpm.august_data, _xlpm.september_data, _xlpm.october_data, _xlpm.november_data, _xlpm.december_data), _xlpm.target_week, B9, SUM( _xlfn.BYROW( _xlpm.all_data, _xlfn.LAMBDA(_xlpm.row, IF( COUNTA(_xlpm.row) >= 3, IF( AND( WEEKNUM(INDEX(_xlpm.row,1),2) = _xlpm.target_week, ISNUMBER(SEARCH("feedback", INDEX(_xlpm.row,2)&"")) ), INDEX(_xlpm.row,3), 0 ), 0 ) ) ) ) )} -> 5.5 | J9: 7 | K9: 0 | L9: =IFERROR(H9/J9 * 60, 0) -> 47.142857
